<?xml version="1.0"?>
<robot xmlns:xacro="http://ros.org/wiki/xacro">
  <xacro:include filename="$(find abb_resources)/urdf/common_materials.xacro"/>

  <xacro:macro name="abb_crb1100_4_58" params="prefix">
    <!-- link list -->
    <link name="${prefix}base_link">
      <visual name="visual">
        <geometry>
          <mesh filename="package://abb_crb1100_support/meshes/crb1100_4_58/base_link.stl"/>
        </geometry>
        <xacro:material_abb_white />
      </visual>
      <collision name"collision">
        <geometry>
          <mesh filename="package://abb_crb1100_support/meshes/crb1100_4_58/base_link.stl"/>
        </geometry>
        <xacro:material_abb_yellow />
      </collision>
    </link>
    <link name="${prefix}link_1">
      <visual>
        <geometry>
          <mesh filename="package://abb_crb1100_support/meshes/crb1100_4_58/link_1.stl"/>
        </geometry>
        <xacro:material_abb_white />
      </visual>
      <collision name="collision">
        <geometry>
          <mesh filename="package://abb_crb1100_support/meshes/crb1100_4_58/link_1.stl"/>
        </geometry>
        <xacro:material_abb_yellow />
      </collision>
    </link>
    <link name="${prefix}link_2">
      <visual>
        <geometry>
          <mesh filename="package://abb_crb1100_support/meshes/crb1100_4_58/link_2.stl"/>
        </geometry>
        <xacro:material_abb_white />
      </visual>
      <collision name="Link2_Box008">
        <geometry>
          <mesh filename="package://abb_crb1100_support/meshes/crb1100_4_58/link_2.stl"/>
        </geometry>
        <xacro:material_abb_yellow />
      </collision>
    </link>
    <link name="${prefix}link_3">
      <visual>
        <geometry>
          <mesh filename="package://abb_crb1100_support/meshes/crb1100_4_58/link_3.stl"/>
        </geometry>
        <xacro:material_abb_white />
      </visual>
      <collision name="collision">
        <geometry>
          <mesh filename="package://abb_crb1100_support/meshes/crb1100_4_58/link_3.stl"/>
        </geometry>
        <xacro:material_abb_yellow />
      </collision>
    </link>
    <link name="${prefix}link_4">
      <visual>
        <geometry>
          <mesh filename="package://abb_crb1100_support/meshes/crb1100_4_58/link_4.stl"/>
        </geometry>
        <xacro:material_abb_white />
      </visual>
      <collision name="collision">
        <geometry>
          <mesh filename="package://abb_crb1100_support/meshes/crb1100_4_58/link_4.stl"/>
        </geometry>
        <xacro:material_abb_yellow />
      </collision>
    </link>
    <link name="{prefix}link_5">
      <visual name="link_5">
        <geometry>
          <mesh filename="package://abb_crb1100_support/meshes/crb1100_4_58/link_5.stl"/>
          <xacro:material_abb_white />
        </geometry>
      </visual>
      <collision name="collision">
        <pose>0.324441 0.0 0.617 1.5708 0.0 -1.5708</pose>
        <geometry>
          <mesh filename="package://abb_crb1100_support/meshes/crb1100_4_58/link_5.stl"/>
          <xacro:material_abb_yellow />
        </geometry>
      </collision>
    </link>
    <link name="{prefix}link_6">
      <visual name="link_6">
        <geometry>
          <mesh filename="package://abb_crb1100_support/meshes/crb1100_4_58/link_6.stl"/>
          <xacro:material_abb_white />
        </geometry>
      </visual>
      <collision name="Link4_Cylinder011">
        <geometry>
          <mesh filename="package://abb_crb1100_support/meshes/crb1100_4_58/link_6.stl"/>
          <xacro:material_abb_yellow />
        </geometry>
      </collision>
    </link>
    <!-- end of link list -->

    <!-- joint list -->
    <joint name="${prefix}joint_1" type="revolute">
      <origin xyz="0 0 0.0" rpy="0 0 0"/>
      <parent link="${prefix}base_link"/>
      <child link="${prefix}link_1"/>
      <axis xyz="0 0 1"/>
      <limit lower="${radians(-230)}" upper="${radians(230)}" effort="1000" velocity="${radians(460)}"/>
      <dynamics damping="10.0" friction="1.0"/>
    </joint>
    <joint name="${prefix}joint_2" type="revolute">
      <origin xyz="0.0 0 0.0" rpy="0 0 0"/>
      <parent link="${prefix}link_1"/>
      <child link="${prefix}link_2"/>
      <axis xyz="0 0 1"/>
      <limit lower="${radians(-115)}" upper="${radians(113)}" effort="1000" velocity="${radians(360)}"/>
      <dynamics damping="2.0" friction="1.0"/>
    </joint>
    <joint name="${prefix}joint_3" type="prismatic">
      <origin xyz="0.0 0 0.0" rpy="0 0 0"/>
      <parent link="${prefix}link_2"/>
      <child link="${prefix}link_3"/>
      <axis xyz="0 0 1"/>
      <limit lower="${radians(-205)}" upper="${radians(55)}" effort="1000" velocity="${radians(280)}"/>
      <dynamics damping="2.0" friction="1.0"/>
    </joint>
    <joint name="${prefix}joint_4" type="revolute">
      <origin xyz="0 0 0" rpy="${radians(180)} 0 ${radians(180)}"/>
      <parent link="${prefix}link_3"/>
      <child link="${prefix}link_4"/>
      <axis xyz="0 0 1"/>
      <!-- Note: Original limits are [-400, 400] -->
      <limit lower="${radians(-230)}" upper="${radians(230)}" effort="1000" velocity="${radians(560)}"/>
      <dynamics damping="2.0" friction="1.0"/>
    </joint>
    <joint name="${prefix}joint_4" type="revolute">
      <origin xyz="0 0 0" rpy="${radians(180)} 0 ${radians(180)}"/>
      <parent link="${prefix}link_3"/>
      <child link="${prefix}link_4"/>
      <axis xyz="0 0 1"/>
      <!-- Note: Original limits are [-400, 400] -->
      <limit lower="${radians(-230)}" upper="${radians(230)}" effort="1000" velocity="${radians(560)}"/>
      <dynamics damping="2.0" friction="1.0"/>
    </joint>
    <joint name="${prefix}joint_4" type="revolute">
      <origin xyz="0 0 0" rpy="${radians(180)} 0 ${radians(180)}"/>
      <parent link="${prefix}link_3"/>
      <child link="${prefix}link_4"/>
      <axis xyz="0 0 1"/>
      <!-- Note: Original limits are [-400, 400] -->
      <limit lower="${radians(-230)}" upper="${radians(230)}" effort="1000" velocity="${radians(560)}"/>
      <dynamics damping="2.0" friction="1.0"/>
    </joint>
    <!-- end of joint list -->

    <!-- ROS-Industrial 'base' frame: base_link to ABB World Coordinates transform -->
    <link name="${prefix}base" />
    <joint name="${prefix}base_link-base" type="fixed">
      <origin xyz="0 0 0" rpy="0 0 0"/>
      <parent link="${prefix}base_link"/>
      <child link="${prefix}base"/>
    </joint>

    <!-- ROS-Industrial 'flange' frame: attachment point for EEF models -->
    <link name="${prefix}flange"/>
    <joint type="fixed" name="${prefix}joint_4-flange">
      <origin xyz="0 0 0" rpy="0 0 0"/>
      <parent link="${prefix}link_4"/>
      <child link="${prefix}flange"/>
    </joint>

    <!-- ROS-Industrial 'tool0' frame: all-zeros tool frame -->
    <link name="${prefix}tool0" />
    <joint name="${prefix}link_4-tool0" type="fixed">
      <origin xyz="0 0 0" rpy="${radians(0)} 0 0" />
      <parent link="${prefix}flange" />
      <child link="${prefix}tool0" />
    </joint>
  </xacro:macro>
</robot>
